Workbook

Sheet 🇱🇰 CSE LIVE PRICES
B1: 🇱🇰 CSE LIVE PRICES — Colombo Stock Exchange
B2: Last updated: 2026-05-29 13:41:50 | Source: cse.lk | Currency: LKR
B3: Symbol | C3: Company Name | D3: Last Price (LKR) | E3: Change (LKR) | F3: Change % | G3: Market Cap (LKR) | H3: Fetched At
B4: COMB.N0000 | C4: COMMERCIAL BANK OF CEYLON PLC | D4: 208 | E4: 2.75 | F4: 0.013398295 | G4: 323619109424 | H4: 2026-05-29 13:41
B5: LOLC.N0000 | C5: L O L C HOLDINGS PLC | D5: 555 | E5: -0.25 | F5: -0.045024764 | G5: 263736000000 | H5: 2026-05-29 13:41
B6: DIAL.N0000 | C6: DIALOG AXIATA PLC | D6: 42 | E6: 0.4 | F6: 0.96153846 | G6: 386414069748 | H6: 2026-05-29 13:41
B7: JKH.N0000 | C7: JOHN KEELLS HOLDINGS PLC | D7: 20.1 | E7: 0 | F7: 0 | G7: 3.5594812e+11 | H7: 2026-05-29 13:41
B8: HNB.N0000 | C8: HATTON NATIONAL BANK PLC | D8: 399 | E8: -1 | F8: -0.25 | G8: 183627053820 | H8: 2026-05-29 13:41
B9: SAMP.N0000 | C9: SAMPATH BANK PLC | D9: 142.75 | E9: -0.25 | F9: -0.17482517 | G9: 167403033490 | H9: 2026-05-29 13:41
B10: NTB.N0000 | C10: NATIONS TRUST BANK PLC | D10: 321 | E10: 3 | F10: 0.94339623 | G10: 92605786908 | H10: 2026-05-29 13:41
B11: GRAN.N0000 | C11: CEYLON GRAIN ELEVATORS PLC | D11: 461 | E11: 1 | F11: 0.2173913 | G11: 27660000000 | H11: 2026-05-29 13:41
B12: CTC.N0000 | C12: CEYLON TOBACCO COMPANY PLC | D12: 1828 | E12: -1.75 | F12: -0.095641481 | G12: 342427816828 | H12: 2026-05-29 13:41
B13: CARS.N0000 | C13: CARSON CUMBERBATCH PLC | D13: 820 | E13: 20 | F13: 0.025 | G13: 161037269480 | H13: 2026-05-29 13:41
B15: ✅ 10 stocks tracked • Run script daily to keep prices updated • python cse_updater.py

Sheet 📊 GAINERS & LOSERS
B1: 📊 TODAY'S MARKET MOVERS — Friday, 29 May 2026
B3: 🟢 TOP GAINERS | G3: 🔴 TOP LOSERS
B4: Symbol | C4: Company | D4: Price (LKR) | E4: Change % | G4: Symbol | H4: Company | I4: Price (LKR) | J4: Change %
B5: ASPH.N0000 | D5: 0 | E5: 0.2 | G5: PARA.N0000 | I5: 0 | J5: -0.097323601
B6: SMOT.N0000 | D6: 0 | E6: 0.1420414 | G6: SINH.N0000 | I6: 0 | J6: -0.041860465
B7: OFEQ.N0000 | D7: 0 | E7: 0.085802742 | G7: NEH.N0000 | I7: 0 | J7: -0.036870897
B8: PHAR.N0000 | D8: 0 | E8: 0.079365079 | G8: SLND.N0000 | I8: 0 | J8: -0.035382416
B9: UBF.N0000 | D9: 0 | E9: 0.076923077 | G9: CITH.N0000 | I9: 0 | J9: -0.035087719
B10: UDPL.N0000 | D10: 0 | E10: 0.07641196 | G10: SHOT.X0000 | I10: 0 | J10: -0.029850746
B11: HNBF.N0000 | D11: 0 | E11: 0.076086957 | G11: CFVF.N0000 | I11: 0 | J11: -0.027472527
B12: ETWO.N0000 | D12: 0 | E12: 0.073015873 | G12: COMD.N0000 | I12: 0 | J12: -0.02745098
B13: LGL.X0000 | D13: 0 | E13: 0.068965517 | G13: COCO.N0000 | I13: 0 | J13: -0.026845638
B14: AUTO.N0000 | D14: 0 | E14: 0.065652522 | G14: KPHL.N0000 | I14: 0 | J14: -0.025423729
B17: 🔥 MOST ACTIVE TRADES (by Volume)
B18: Symbol | C18: Company | D18: Price (LKR) | E18: Volume
B19: HNBF.N0000 | D19: 0 | E19: 0
B20: SAMP.N0000 | D20: 0 | E20: 0
B21: JKH.N0000 | D21: 0 | E21: 0
B22: DIAL.N0000 | D22: 0 | E22: 0
B23: CWL.N0000 | D23: 0 | E23: 0
B24: HNBF.X0000 | D24: 0 | E24: 0
B25: COMB.N0000 | D25: 0 | E25: 0
B26: CIC.N0000 | D26: 0 | E26: 0
B27: HNB.N0000 | D27: 0 | E27: 0
B28: AEL.N0000 | D28: 0 | E28: 0

Sheet 📋 HOW IT WORKS
B1: 🇱🇰 CSE STOCK MARKET TREND ANALYZER
B2: Colombo Stock Exchange • Automated Daily Tracker • All prices in LKR
B4: 💡 WHAT THIS FILE DOES
B5: ✅ Tracks real CSE stock prices — fetched directly from cse.lk
B6: ✅ Builds your price history automatically — one new row added every day you run the script
B7: ✅ Calculates moving averages & BUY/SELL signals automatically using Excel formulas
B8: ✅ Shows interactive charts that update themselves as new data arrives
B9: ✅ Displays today's top gainers, losers & most active CSE stocks
B10: ✅ Zero manual data entry — just run the Python script and open this file
B12: 🤖 HOW THE AUTOMATION WORKS
B13: STEP 1 | C13: Run the Python script | D13: ↓ runs automatically
C14: Open Command Prompt → go to your project folder → type: python cse_updater.py Then press Enter.
B16: STEP 2 | C16: Script fetches live CSE data | D16: ↓ runs automatically
C17: It connects to cse.lk API and downloads: • Today's price for your primary stock (COMB.N0000) • Live prices for all 10 tracked stocks • Today's top gainers, losers & most active
B19: STEP 3 | C19: RAW DATA sheet gets a new row | D19: ↓ runs automatically
C20: Today's Date, Open, High, Low, Close, Volume is automatically added to the RAW DATA sheet. Run it tomorrow → another row is added. And so on.
B22: STEP 4 | C22: ANALYSIS sheet auto-calculates | D22: ↓ runs automatically
C23: Excel formulas instantly recalculate: • Daily Return % • 7-Day Moving Average • 20-Day Moving Average • BUY/SELL Signals
B25: STEP 5 | C25: DASHBOARD updates automatically | D25: 🎉 Done!
C26: Charts and KPI cards refresh from the new data. No clicking. No manual work. Just open the file!
B29: 📂 WHAT EACH SHEET DOES
C30: 📋 HOW IT WORKS | D30: → This sheet — read it first!
C31: Full guide to understand the file and the automation.
C33: 🇱🇰 CSE LIVE PRICES | D33: → Updated every time you run the script
C34: Shows real-time prices, change %, and market cap for all 10 tracked stocks.
C36: 📊 GAINERS & LOSERS | D36: → Updated every time you run the script
C37: Today's top 10 gaining stocks, top 10 losing stocks, and most active trades.
C39: 📊 RAW DATA | D39: → Grows by 1 row every trading day
C40: Stores the price history for COMB.N0000. Date, Open, High, Low, Close, Volume.
C42: 🔬 ANALYSIS | D42: → Auto-calculates from RAW DATA
C43: Daily Return %, 7-Day MA, 20-Day MA, BUY/SELL signals — all Excel formulas.
C45: 📈 DASHBOARD | D45: → Auto-updates from ANALYSIS
C46: KPI cards + 2 charts (Price & Moving Averages, Daily Return %).
B49: ➕ HOW TO ADD MORE STOCKS
B50: 1 | C50: Open cse_updater.py in Notepad (right-click → Open with → Notepad)
B51: 2 | C51: Find the section that says STOCKS_TO_TRACK near the top
B52: 3 | C52: Add a new line inside the list: "SAMP.N0000", # Sampath Bank
B53: 4 | C53: Save the file (Ctrl+S) and run: python cse_updater.py
B54: 5 | C54: The new stock appears in the Live Prices sheet automatically
C55: 💡 Find any CSE stock symbol at: www.cse.lk (format is always SYMBOL.N0000)
...

Sheet 📊 RAW DATA
B1: 📊 RAW DATA — COMB.N0000 (Commercial Bank of Ceylon) • LKR
B2: One new row is added here automatically every day you run: python cse_updater.py
B3: 2026-05-29 | C3: 207 | D3: 208.25 | E3: 206 | F3: 208 | G3: 0
B4: ⚠️ DO NOT manually edit this sheet — the script manages it automatically. Do NOT change column order or delete rows.
B5: Date | C5: Open (LKR) | D5: High (LKR) | E5: Low (LKR) | F5: Close (LKR) | G5: Volume
B6: Trading date (YYYY-MM-DD) | C6: Opening price of the day | D6: Highest price of the day | E6: Lowest price of the day | F6: Closing price ← most important | G6: Number of shares traded
B7: 2025-10-01 | C7: 199.9 | D7: 199.99 | E7: 199.13 | F7: 199.69 | G7: 1064275
B8: 2025-10-02 | C8: 199.89 | D8: 200.1 | E8: 196.81 | F8: 196.98 | G8: 1132447
B9: 2025-10-03 | C9: 197.67 | D9: 198.73 | E9: 197.58 | F9: 198.21 | G9: 893269
B10: 2025-10-06 | C10: 198.36 | D10: 199.4 | E10: 196.4 | F10: 196.43 | G10: 1070229
B11: 2025-10-07 | C11: 195.57 | D11: 196.94 | E11: 195.19 | F11: 196.69 | G11: 1344553
B12: 2025-10-08 | C12: 196.91 | D12: 197.11 | E12: 195.9 | F12: 196.51 | G12: 788297
B13: 2025-10-09 | C13: 195.62 | D13: 198.87 | E13: 195.15 | F13: 196.81 | G13: 843573
B14: 2025-10-10 | C14: 197.2 | D14: 199.98 | E14: 196.53 | F14: 199.01 | G14: 819383
B15: 2025-10-13 | C15: 198.83 | D15: 198.92 | E15: 198.09 | F15: 198.74 | G15: 1278755
B16: 2025-10-14 | C16: 199.13 | D16: 200.29 | E16: 198.63 | F16: 199.91 | G16: 899136
B17: 2025-10-15 | C17: 200.21 | D17: 200.41 | E17: 197.49 | F17: 199.35 | G17: 870598
B18: 2025-10-16 | C18: 199.81 | D18: 200.95 | E18: 197.29 | F18: 197.69 | G18: 1334028
... B136: 2026-03-31 | C136: 240.73 | D136: 241.63 | E136: 237.76 | F136: 238.77 | G136: 1157663

Sheet 🔬 ANALYSIS
B1: 🔬 ANALYSIS — COMB.N0000 • All formulas auto-calculate from RAW DATA
B2: DO NOT edit this sheet — everything updates automatically when RAW DATA changes
B4: Date from RAW DATA | C4: Closing price (LKR) | D4: % change vs yesterday | E4: Avg of last 7 closes | F4: Avg of last 20 closes | G4: 7MA minus 20MA % | H4: BUY▲ or SELL▼ | I4: Plain English explanation
B5: Date | C5: Close (LKR) | D5: Daily Return % | E5: 7-Day MA | F5: 20-Day MA | G5: MA Diff % | H5: Signal | I5: What It Means
B6: ='📊 RAW DATA'!B7 -> 2025-10-01 | C6: ='📊 RAW DATA'!F7 -> 199.69 | D6: "" | E6: =IF(ROW()-5<7,"",AVERAGE(c0:C6)) | G6: =IF(OR(E6="",F6=""),"",(E6-F6)/F6) | H6: =IF(OR(E6="",F6=""),"WAIT",IF(E6>F6,"BUY ▲","SELL ▼")) -> WAIT | I6: =IF(H6="WAIT","Need more data (20 days minimum)",IF(H6="BUY ▲","7-Day MA above 20-Day MA — upward momentum — possible good time to buy","7-Day MA below 20-Day MA — downward momentum — possible time to be cautious")) -> Need more data (20 days minimum)
B7: ='📊 RAW DATA'!B8 -> 2025-10-02 | C7: ='📊 RAW DATA'!F8 -> 196.98 | D7: =IF(C6=0,"",C7/C6-1) -> -0.013571035 | E7: =IF(ROW()-5<7,"",AVERAGE(C1:C7)) | G7: =IF(OR(E7="",F7=""),"",(E7-F7)/F7) | H7: =IF(OR(E7="",F7=""),"WAIT",IF(E7>F7,"BUY ▲","SELL ▼")) -> WAIT | I7: =IF(H7="WAIT","Need more data (20 days minimum)",IF(H7="BUY ▲","7-Day MA above 20-Day MA — upward momentum — possible good time to buy","7-Day MA below 20-Day MA — downward momentum — possible time to be cautious")) -> Need more data (20 days minimum)
B8: ='📊 RAW DATA'!B9 -> 2025-10-03 | C8: ='📊 RAW DATA'!F9 -> 198.21 | D8: =IF(C7=0,"",C8/C7-1) -> 0.0062442888 | E8: =IF(ROW()-5<7,"",AVERAGE(C2:C8)) | G8: =IF(OR(E8="",F8=""),"",(E8-F8)/F8) | H8: =IF(OR(E8="",F8=""),"WAIT",IF(E8>F8,"BUY ▲","SELL ▼")) -> WAIT | I8: =IF(H8="WAIT","Need more data (20 days minimum)",IF(H8="BUY ▲","7-Day MA above 20-Day MA — upward momentum — possible good time to buy","7-Day MA below 20-Day MA — downward momentum — possible time to be cautious")) -> Need more data (20 days minimum)
B9: ='📊 RAW DATA'!B10 -> 2025-10-06 | C9: ='📊 RAW DATA'!F10 -> 196.43 | D9: =IF(C8=0,"",C9/C8-1) -> -0.0089803744 | E9: =IF(ROW()-5<7,"",AVERAGE(C3:C9)) | G9: =IF(OR(E9="",F9=""),"",(E9-F9)/F9) | H9: =IF(OR(E9="",F9=""),"WAIT",IF(E9>F9,"BUY ▲","SELL ▼")) -> WAIT | I9: =IF(H9="WAIT","Need more data (20 days minimum)",IF(H9="BUY ▲","7-Day MA above 20-Day MA — upward momentum — possible good time to buy","7-Day MA below 20-Day MA — downward momentum — possible time to be cautious")) -> Need more data (20 days minimum)
B10: ='📊 RAW DATA'!B11 -> 2025-10-07 | C10: ='📊 RAW DATA'!F11 -> 196.69 | D10: =IF(C9=0,"",C10/C9-1) -> 0.0013236267 | E10: =IF(ROW()-5<7,"",AVERAGE(C4:C10)) | G10: =IF(OR(E10="",F10=""),"",(E10-F10)/F10) | H10: =IF(OR(E10="",F10=""),"WAIT",IF(E10>F10,"BUY ▲","SELL ▼")) -> WAIT | I10: =IF(H10="WAIT","Need more data (20 days minimum)",IF(H10="BUY ▲","7-Day MA above 20-Day MA — upward momentum — possible good time to buy","7-Day MA below 20-Day MA — downward momentum — possible time to be cautious")) -> Need more data (20 days minimum)
B11: ='📊 RAW DATA'!B12 -> 2025-10-08 | C11: ='📊 RAW DATA'!F12 -> 196.51 | D11: =IF(C10=0,"",C11/C10-1) -> -0.00091514566 | E11: =IF(ROW()-5<7,"",AVERAGE(C5:C11)) | G11: =IF(OR(E11="",F11=""),"",(E11-F11)/F11) | H11: =IF(OR(E11="",F11=""),"WAIT",IF(E11>F11,"BUY ▲","SELL ▼")) -> WAIT | I11: =IF(H11="WAIT","Need more data (20 days minimum)",IF(H11="BUY ▲","7-Day MA above 20-Day MA — upward momentum — possible good time to buy","7-Day MA below 20-Day MA — downward momentum — possible time to be cautious")) -> Need more data (20 days minimum)
B12: ='📊 RAW DATA'!B13 -> 2025-10-09 | C12: ='📊 RAW DATA'!F13 -> 196.81 | D12: =IF(C11=0,"",C12/C11-1) -> 0.0015266399 | E12: =IF(ROW()-5<7,"",AVERAGE(C6:C12)) -> 197.33143 | G12: =IF(OR(E12="",F12=""),"",(E12-F12)/F12) | H12: =IF(OR(E12="",F12=""),"WAIT",IF(E12>F12,"BUY ▲","SELL ▼")) -> WAIT | I12: =IF(H12="WAIT","Need more data (20 days minimum)",IF(H12="BUY ▲","7-Day MA above 20-Day MA — upward momentum — possible good time to buy","7-Day MA below 20-Day MA — downward momentum — possible time to be cautious")) -> Need more data (20 days minimum)
B13: ='📊 RAW DATA'!B14 -> 2025-10-10 | C13: ='📊 RAW DATA'!F14 -> 199.01 | D13: =IF(C12=0,"",C13/C12-1) -> 0.011178294 | E13: =IF(ROW()-5<7,"",AVERAGE(C7:C13)) -> 197.23429 | G13: =IF(OR(E13="",F13=""),"",(E13-F13)/F13) | H13: =IF(OR(E13="",F13=""),"WAIT",IF(E13>F13,"BUY ▲","SELL ▼")) -> WAIT | I13: =IF(H13="WAIT","Need more data (20 days minimum)",IF(H13="BUY ▲","7-Day MA above 20-Day MA — upward momentum — possible good time to buy","7-Day MA below 20-Day MA — downward momentum — possible time to be cautious")) -> Need more data (20 days minimum)
B14: ='📊 RAW DATA'!B15 -> 2025-10-13 | C14: ='📊 RAW DATA'!F15 -> 198.74 | D14: =IF(C13=0,"",C14/C13-1) -> -0.0013567157 | E14: =IF(ROW()-5<7,"",AVERAGE(C8:C14)) -> 197.48571 | G14: =IF(OR(E14="",F14=""),"",(E14-F14)/F14) | H14: =IF(OR(E14="",F14=""),"WAIT",IF(E14>F14,"BUY ▲","SELL ▼")) -> WAIT | I14: =IF(H14="WAIT","Need more data (20 days minimum)",IF(H14="BUY ▲","7-Day MA above 20-Day MA — upward momentum — possible good time to buy","7-Day MA below 20-Day MA — downward momentum — possible time to be cautious")) -> Need more data (20 days minimum)
B15: ='📊 RAW DATA'!B16 -> 2025-10-14 | C15: ='📊 RAW DATA'!F16 -> 199.91 | D15: =IF(C14=0,"",C15/C14-1) -> 0.0058870887 | E15: =IF(ROW()-5<7,"",AVERAGE(C9:C15)) -> 197.72857 | G15: =IF(OR(E15="",F15=""),"",(E15-F15)/F15) | H15: =IF(OR(E15="",F15=""),"WAIT",IF(E15>F15,"BUY ▲","SELL ▼")) -> WAIT | I15: =IF(H15="WAIT","Need more data (20 days minimum)",IF(H15="BUY ▲","7-Day MA above 20-Day MA — upward momentum — possible good time to buy","7-Day MA below 20-Day MA — downward momentum — possible time to be cautious")) -> Need more data (20 days minimum)
B16: ='📊 RAW DATA'!B17 -> 2025-10-15 | C16: ='📊 RAW DATA'!F17 -> 199.35 | D16: =IF(C15=0,"",C16/C15-1) -> -0.0028012606 | E16: =IF(ROW()-5<7,"",AVERAGE(C10:C16)) -> 198.14571 | G16: =IF(OR(E16="",F16=""),"",(E16-F16)/F16) | H16: =IF(OR(E16="",F16=""),"WAIT",IF(E16>F16,"BUY ▲","SELL ▼")) -> WAIT | I16: =IF(H16="WAIT","Need more data (20 days minimum)",IF(H16="BUY ▲","7-Day MA above 20-Day MA — upward momentum — possible good time to buy","7-Day MA below 20-Day MA — downward momentum — possible time to be cautious")) -> Need more data (20 days minimum)
B17: ='📊 RAW DATA'!B18 -> 2025-10-16 | C17: ='📊 RAW DATA'!F18 -> 197.69 | D17: =IF(C16=0,"",C17/C16-1) -> -0.008327063 | E17: =IF(ROW()-5<7,"",AVERAGE(C11:C17)) -> 198.28857 | G17: =IF(OR(E17="",F17=""),"",(E17-F17)/F17) | H17: =IF(OR(E17="",F17=""),"WAIT",IF(E17>F17,"BUY ▲","SELL ▼")) -> WAIT | I17: =IF(H17="WAIT","Need more data (20 days minimum)",IF(H17="BUY ▲","7-Day MA above 20-Day MA — upward momentum — possible good time to buy","7-Day MA below 20-Day MA — downward momentum — possible time to be cautious")) -> Need more data (20 days minimum)
B18: ='📊 RAW DATA'!B19 -> 2025-10-17 | C18: ='📊 RAW DATA'!F19 -> 200.53 | D18: =IF(C17=0,"",C18/C17-1) -> 0.014365926 | E18: =IF(ROW()-5<7,"",AVERAGE(C12:C18)) -> 198.86286 | G18: =IF(OR(E18="",F18=""),"",(E18-F18)/F18) | H18: =IF(OR(E18="",F18=""),"WAIT",IF(E18>F18,"BUY ▲","SELL ▼")) -> WAIT | I18: =IF(H18="WAIT","Need more data (20 days minimum)",IF(H18="BUY ▲","7-Day MA above 20-Day MA — upward momentum — possible good time to buy","7-Day MA below 20-Day MA — downward momentum — possible time to be cautious")) -> Need more data (20 days minimum)
B19: ='📊 RAW DATA'!B20 -> 2025-10-20 | C19: ='📊 RAW DATA'!F20 -> 197.73 | D19: =IF(C18=0,"",C19/C18-1) -> -0.013962998 | E19: =IF(ROW()-5<7,"",AVERAGE(C13:C19)) -> 198.99429 | F19: =IF(ROW()-5<20,"",AVERAGE(c0:C19)) | G19: =IF(OR(E19="",F19=""),"",(E19-F19)/F19) | H19: =IF(OR(E19="",F19=""),"WAIT",IF(E19>F19,"BUY ▲","SELL ▼")) -> WAIT | I19: =IF(H19="WAIT","Need more data (20 days minimum)",IF(H19="BUY ▲","7-Day MA above 20-Day MA — upward momentum — possible good time to buy","7-Day MA below 20-Day MA — downward momentum — possible time to be cautious")) -> Need more data (20 days minimum)
B20: ='📊 RAW DATA'!B21 -> 2025-10-21 | C20: ='📊 RAW DATA'!F21 -> 200.35 | D20: =IF(C19=0,"",C20/C19-1) -> 0.013250392 | E20: =IF(ROW()-5<7,"",AVERAGE(C14:C20)) -> 199.18571 | F20: =IF(ROW()-5<20,"",AVERAGE(C1:C20)) | G20: =IF(OR(E20="",F20=""),"",(E20-F20)/F20) | H20: =IF(OR(E20="",F20=""),"WAIT",IF(E20>F20,"BUY ▲","SELL ▼")) -> WAIT | I20: =IF(H20="WAIT","Need more data (20 days minimum)",IF(H20="BUY ▲","7-Day MA above 20-Day MA — upward momentum — possible good time to buy","7-Day MA below 20-Day MA — downward momentum — possible time to be cautious")) -> Need more data (20 days minimum)
B21: ='📊 RAW DATA'!B22 -> 2025-10-22 | C21: ='📊 RAW DATA'!F22 -> 199.33 | D21: =IF(C20=0,"",C21/C20-1) -> -0.0050910906 | E21: =IF(ROW()-5<7,"",AVERAGE(C15:C21)) -> 199.27 | F21: =IF(ROW()-5<20,"",AVERAGE(C2:C21)) | G21: =IF(OR(E21="",F21=""),"",(E21-F21)/F21) | H21: =IF(OR(E21="",F21=""),"WAIT",IF(E21>F21,"BUY ▲","SELL ▼")) -> WAIT | I21: =IF(H21="WAIT","Need more data (20 days minimum)",IF(H21="BUY ▲","7-Day MA above 20-Day MA — upward momentum — possible good time to buy","7-Day MA below 20-Day MA — downward momentum — possible time to be cautious")) -> Need more data (20 days minimum)
B22: ='📊 RAW DATA'!B23 -> 2025-10-23 | C22: ='📊 RAW DATA'!F23 -> 197.79 | D22: =IF(C21=0,"",C22/C21-1) -> -0.0077258817 | E22: =IF(ROW()-5<7,"",AVERAGE(C16:C22)) -> 198.96714 | F22: =IF(ROW()-5<20,"",AVERAGE(C3:C22)) | G22: =IF(OR(E22="",F22=""),"",(E22-F22)/F22) | H22: =IF(OR(E22="",F22=""),"WAIT",IF(E22>F22,"BUY ▲","SELL ▼")) -> WAIT | I22: =IF(H22="WAIT","Need more data (20 days minimum)",IF(H22="BUY ▲","7-Day MA above 20-Day MA — upward momentum — possible good time to buy","7-Day MA below 20-Day MA — downward momentum — possible time to be cautious")) -> Need more data (20 days minimum)
B23: ='📊 RAW DATA'!B24 -> 2025-10-24 | C23: ='📊 RAW DATA'!F24 -> 199.4 | D23: =IF(C22=0,"",C23/C22-1) -> 0.0081399464 | E23: =IF(ROW()-5<7,"",AVERAGE(C17:C23)) -> 198.97429 | F23: =IF(ROW()-5<20,"",AVERAGE(C4:C23)) | G23: =IF(OR(E23="",F23=""),"",(E23-F23)/F23) | H23: =IF(OR(E23="",F23=""),"WAIT",IF(E23>F23,"BUY ▲","SELL ▼")) -> WAIT | I23: =IF(H23="WAIT","Need more data (20 days minimum)",IF(H23="BUY ▲","7-Day MA above 20-Day MA — upward momentum — possible good time to buy","7-Day MA below 20-Day MA — downward momentum — possible time to be cautious")) -> Need more data (20 days minimum)
B24: ='📊 RAW DATA'!B25 -> 2025-10-27 | C24: ='📊 RAW DATA'!F25 -> 202.18 | D24: =IF(C23=0,"",C24/C23-1) -> 0.013941825 | E24: =IF(ROW()-5<7,"",AVERAGE(C18:C24)) -> 199.61571 | F24: =IF(ROW()-5<20,"",AVERAGE(C5:C24)) | G24: =IF(OR(E24="",F24=""),"",(E24-F24)/F24) | H24: =IF(OR(E24="",F24=""),"WAIT",IF(E24>F24,"BUY ▲","SELL ▼")) -> WAIT | I24: =IF(H24="WAIT","Need more data (20 days minimum)",IF(H24="BUY ▲","7-Day MA above 20-Day MA — upward momentum — possible good time to buy","7-Day MA below 20-Day MA — downward momentum — possible time to be cautious")) -> Need more data (20 days minimum)
B25: ='📊 RAW DATA'!B26 -> 2025-10-28 | C25: ='📊 RAW DATA'!F26 -> 203.77 | D25: =IF(C24=0,"",C25/C24-1) -> 0.0078642794 | E25: =IF(ROW()-5<7,"",AVERAGE(C19:C25)) -> 200.07857 | F25: =IF(ROW()-5<20,"",AVERAGE(C6:C25)) -> 198.855 | G25: =IF(OR(E25="",F25=""),"",(E25-F25)/F25) -> 0.0061530835 | H25: =IF(OR(E25="",F25=""),"WAIT",IF(E25>F25,"BUY ▲","SELL ▼")) -> BUY ▲ | I25: =IF(H25="WAIT","Need more data (20 days minimum)",IF(H25="BUY ▲","7-Day MA above 20-Day MA — upward momentum — possible good time to buy","7-Day MA below 20-Day MA — downward momentum — possible time to be cautious")) -> 7-Day MA above 20-Day MA — upward momentum — possible good time to buy
B26: ='📊 RAW DATA'!B27 -> 2025-10-29 | C26: ='📊 RAW DATA'!F27 -> 207.17 | D26: =IF(C25=0,"",C26/C25-1) -> 0.016685479 | E26: =IF(ROW()-5<7,"",AVERAGE(C20:C26)) -> 201.42714 | F26: =IF(ROW()-5<20,"",AVERAGE(C7:C26)) -> 199.229 | G26: =IF(OR(E26="",F26=""),"",(E26-F26)/F26) -> 0.011033247 | H26: =IF(OR(E26="",F26=""),"WAIT",IF(E26>F26,"BUY ▲","SELL ▼")) -> BUY ▲ | I26: =IF(H26="WAIT","Need more data (20 days minimum)",IF(H26="BUY ▲","7-Day MA above 20-Day MA — upward momentum — possible good time to buy","7-Day MA below 20-Day MA — downward momentum — possible time to be cautious")) -> 7-Day MA above 20-Day MA — upward momentum — possible good time to buy
B27: ='📊 RAW DATA'!B28 -> 2025-10-30 | C27: ='📊 RAW DATA'!F28 -> 210.72 | D27: =IF(C26=0,"",C27/C26-1) -> 0.017135686 | E27: =IF(ROW()-5<7,"",AVERAGE(C21:C27)) -> 202.90857 | F27: =IF(ROW()-5<20,"",AVERAGE(C8:C27)) -> 199.916 | G27: =IF(OR(E27="",F27=""),"",(E27-F27)/F27) -> 0.014969144 | H27: =IF(OR(E27="",F27=""),"WAIT",IF(E27>F27,"BUY ▲","SELL ▼")) -> BUY ▲ | I27: =IF(H27="WAIT","Need more data (20 days minimum)",IF(H27="BUY ▲","7-Day MA above 20-Day MA — upward momentum — possible good time to buy","7-Day MA below 20-Day MA — downward momentum — possible time to be cautious")) -> 7-Day MA above 20-Day MA — upward momentum — possible good time to buy
B28: ='📊 RAW DATA'!B29 -> 2025-10-31 | C28: ='📊 RAW DATA'!F29 -> 211.62 | D28: =IF(C27=0,"",C28/C27-1) -> 0.0042710706 | E28: =IF(ROW()-5<7,"",AVERAGE(C22:C28)) -> 204.66429 | F28: =IF(ROW()-5<20,"",AVERAGE(C9:C28)) -> 200.5865 | G28: =IF(OR(E28="",F28=""),"",(E28-F28)/F28) -> 0.020329313 | H28: =IF(OR(E28="",F28=""),"WAIT",IF(E28>F28,"BUY ▲","SELL ▼")) -> BUY ▲ | I28: =IF(H28="WAIT","Need more data (20 days minimum)",IF(H28="BUY ▲","7-Day MA above 20-Day MA — upward momentum — possible good time to buy","7-Day MA below 20-Day MA — downward momentum — possible time to be cautious")) -> 7-Day MA above 20-Day MA — upward momentum — possible good time to buy
B29: ='📊 RAW DATA'!B30 -> 2025-11-03 | C29: ='📊 RAW DATA'!F30 -> 209.2 | D29: =IF(C28=0,"",C29/C28-1) -> -0.011435592 | E29: =IF(ROW()-5<7,"",AVERAGE(C23:C29)) -> 206.29429 | F29: =IF(ROW()-5<20,"",AVERAGE(C10:C29)) -> 201.225 | G29: =IF(OR(E29="",F29=""),"",(E29-F29)/F29) -> 0.025192127 | H29: =IF(OR(E29="",F29=""),"WAIT",IF(E29>F29,"BUY ▲","SELL ▼")) -> BUY ▲ | I29: =IF(H29="WAIT","Need more data (20 days minimum)",IF(H29="BUY ▲","7-Day MA above 20-Day MA — upward momentum — possible good time to buy","7-Day MA below 20-Day MA — downward momentum — possible time to be cautious")) -> 7-Day MA above 20-Day MA — upward momentum — possible good time to buy
B30: ='📊 RAW DATA'!B31 -> 2025-11-04 | C30: ='📊 RAW DATA'!F31 -> 208.71 | D30: =IF(C29=0,"",C30/C29-1) -> -0.0023422562 | E30: =IF(ROW()-5<7,"",AVERAGE(C24:C30)) -> 207.62429 | F30: =IF(ROW()-5<20,"",AVERAGE(C11:C30)) -> 201.826 | G30: =IF(OR(E30="",F30=""),"",(E30-F30)/F30) -> 0.028729132 | H30: =IF(OR(E30="",F30=""),"WAIT",IF(E30>F30,"BUY ▲","SELL ▼")) -> BUY ▲ | I30: =IF(H30="WAIT","Need more data (20 days minimum)",IF(H30="BUY ▲","7-Day MA above 20-Day MA — upward momentum — possible good time to buy","7-Day MA below 20-Day MA — downward momentum — possible time to be cautious")) -> 7-Day MA above 20-Day MA — upward momentum — possible good time to buy
B31: ='📊 RAW DATA'!B32 -> 2025-11-05 | C31: ='📊 RAW DATA'!F32 -> 210.23 | D31: =IF(C30=0,"",C31/C30-1) -> 0.0072828326 | E31: =IF(ROW()-5<7,"",AVERAGE(C25:C31)) -> 208.77429 | F31: =IF(ROW()-5<20,"",AVERAGE(C12:C31)) -> 202.512 | G31: =IF(OR(E31="",F31=""),"",(E31-F31)/F31) -> 0.030923035 | H31: =IF(OR(E31="",F31=""),"WAIT",IF(E31>F31,"BUY ▲","SELL ▼")) -> BUY ▲ | I31: =IF(H31="WAIT","Need more data (20 days minimum)",IF(H31="BUY ▲","7-Day MA above 20-Day MA — upward momentum — possible good time to buy","7-Day MA below 20-Day MA — downward momentum — possible time to be cautious")) -> 7-Day MA above 20-Day MA — upward momentum — possible good time to buy
... B135: ='📊 RAW DATA'!B136 -> 2026-03-31 | C135: ='📊 RAW DATA'!F136 -> 238.77 | D135: =IF(C134=0,"",C135/C134-1) -> -0.0054150873 | E135: =IF(ROW()-5<7,"",AVERAGE(C129:C135)) -> 235.73571 | F135: =IF(ROW()-5<20,"",AVERAGE(C116:C135)) -> 233.586 | G135: =IF(OR(E135="",F135=""),"",(E135-F135)/F135) -> 0.0092030956 | H135: =IF(OR(E135="",F135=""),"WAIT",IF(E135>F135,"BUY ▲","SELL ▼")) -> BUY ▲ | I135: =IF(H135="WAIT","Need more data (20 days minimum)",IF(H135="BUY ▲","7-Day MA above 20-Day MA — upward momentum — possible good time to buy","7-Day MA below 20-Day MA — downward momentum — possible time to be cautious")) -> 7-Day MA above 20-Day MA — upward momentum — possible good time to buy

Sheet 📈 DASHBOARD
B1: 📈 CSE STOCK TREND ANALYZER — DASHBOARD 🇱🇰
B2: COMB.N0000 (Commercial Bank of Ceylon) • Sample: Oct 2025–Mar 2026 • Run cse_updater.py daily to update • LKR
B4: 🏁 START PRICE (LKR) | I4: 🏆 LATEST PRICE (LKR) | P4: 📈 TOTAL RETURN | W4: 📊 LATEST SIGNAL
B5: ='📊 RAW DATA'!F7 -> 199.69 | I5: ='📊 RAW DATA'!F136 -> 238.77 | P5: =('📊 RAW DATA'!F136-'📊 RAW DATA'!F7)/'📊 RAW DATA'!F7 -> 0.19570334 | W5: ='🔬 ANALYSIS'!H135 -> BUY ▲
B34: 📖 HOW TO READ THIS DASHBOARD
B35: Blue Line = Close Price | L35: The actual CSE stock price each trading day in LKR.
B36: Orange Line = 7-Day MA | L36: Average of last 7 closing prices. Reacts fast to price movements.
B37: Red Line = 20-Day MA | L37: Average of last 20 closing prices. Shows the overall trend direction.
B38: BUY ▲ (green cell in ANALYSIS) | L38: 7-Day MA crossed above 20-Day MA — price gaining upward momentum.
B39: SELL ▼ (red cell in ANALYSIS) | L39: 7-Day MA crossed below 20-Day MA — price losing momentum.
B40: How to update charts with real data | L40: Run python cse_updater.py every trading day — data grows automatically!
